# Diagnosis Report: LanguageSwitcher Test Discrepancy (cr_langswitcher_test_fix_20250513T143057)

## 1. Introduction

This report diagnoses discrepancies related to the test 'LanguageSwitcher Component â€º logs structured error and shows specific message on API server error (500)' located in [`__tests__/components/LanguageSwitcher.test.tsx:210`]. The original issue reported (signal `error-testfail-langswitch-2025-05-13T22:30:00.000Z`) indicated that `logger.error` was called twice, while the test currently expects it to be called once and passes when run as part of the suite.

## 2. Analysis of Current Test and Component Behavior

### Test File: [`__tests__/components/LanguageSwitcher.test.tsx`]
- The test at line 210, `'logs structured error and shows specific message on API server error (500)'`, correctly mocks a `fetch` call to return a 500 server error.
- It asserts `expect(logger.error).toHaveBeenCalledTimes(1);` (line 211).
- The "Tester Findings" indicate this test passes when run with the suite, which is consistent with its current assertion.
- The finding that the test "is skipped when run individually" is an environmental or configuration concern outside the scope of this code-level diagnosis but should be investigated to ensure test reliability.

### Component File: [`components/LanguageSwitcher.tsx`]
The error handling logic in the `updatePreference` function is structured as follows:
- A `try...catch` block surrounds the API call.
- If `fetch` returns a non-OK response (e.g., status 500), the `if (!response.ok)` block (lines 44-62) is executed:
    - `logger.error` is called (line 53).
    - `setApiError(t('updatePreferenceErrorServer'))` is called (line 56 for a 500 error).
- If any error occurs during the `try` block execution (including a synchronous error from `setApiError` or a network error from `fetch`), the `catch (error: any)` block (lines 66-83) is executed:
    - `logger.error` is called again (line 75).

## 3. Diagnosis of the Discrepancy and Original Bug

**Why the test currently passes (and doesn't show the double log):**
The test correctly simulates a 500 error, triggering the `if (!response.ok)` block and the first `logger.error` call. In the current React Testing Library environment, the subsequent call to `setApiError` does *not* appear to throw a synchronous error. Therefore, the `catch` block is not entered for this reason, and only one `logger.error` call occurs, matching the test's expectation.

**Confirmation of the Potential Bug (Double `logger.error`):**
The originally reported bug (double `logger.error` call) is indeed possible due to the component's code structure. The "Code Comprehension Hypothesis" is valid:
1. First `logger.error` call occurs in the `if (!response.ok)` block.
2. If the subsequent `setApiError()` call within that same block were to throw a synchronous error, that error would be caught by the outer `catch` block.
3. This would lead to the second `logger.error` call from within the `catch` block.

The original test failure likely occurred in an environment or under specific conditions where `setApiError` *did* throw a synchronous error. This could be due to React version differences, specific component state, or other environmental factors at the time of the original report.

## 4. Reproducing the Original Bug

To reliably reproduce the originally reported failure (i.e., make `logger.error` be called twice) and confirm this bug pathway, the test needs to be modified to simulate `setApiError` throwing an error.

**Proposed Test Modification (Conceptual):**
One way to achieve this is by using `jest.spyOn` to temporarily mock `React.useState` for the specific test case, making the `setter` function (in this case, `setApiError`) throw an error upon invocation.

```typescript
// In __tests__/components/LanguageSwitcher.test.tsx
// ... (other mocks and setup)

it('SHOULD REPRODUCE DOUBLE LOG: logs error twice if setApiError throws after initial log for 500', async () => {
  const originalFetch = global.fetch;
  const mockFailedFetch = jest.fn(() =>
    Promise.resolve(
      new Response(JSON.stringify({ error: 'Simulated API update failed' }), {
        status: 500,
        statusText: 'Internal Server Error',
        headers: { 'Content-Type': 'application/json' }
      })
    )
  );
  global.fetch = mockFailedFetch as any;
  (logger.error as jest.Mock).mockClear();

  // --- Modification Start ---
  const originalUseState = React.useState;
  const errorFromSetApiError = new Error('Simulated synchronous error from setApiError');
  const mockSetApiError = jest.fn(() => { throw errorFromSetApiError; });
  
  // Temporarily spy on React.useState
  // This targets the useState call for apiError in LanguageSwitcher
  const useStateSpy = jest.spyOn(React, 'useState');
  useStateSpy.mockImplementationOnce((initialValue) => {
      // Assuming the apiError state is the one we want to intercept.
      // This might need adjustment if there are other useState calls before it in the component.
      // A more robust way would be to identify it by initial value if unique, or by order.
      // For this example, let's assume it's the first useState or identifiable.
      if (initialValue === null) { // Assuming apiError is initialized to null
          return [initialValue, mockSetApiError] as any;
      }
      // Fallback to original for other useState calls if any
      return originalUseState(initialValue);
  });
  // --- Modification End ---

  render(<LanguageSwitcher />);
  const dropdown = screen.getByRole('combobox');
  
  // Act: Trigger the error path
  fireEvent.change(dropdown, { target: { value: 'es' } });

  await act(async () => {
    await new Promise(resolve => setTimeout(resolve, 0)); // Wait for promises
  });

  // Assert: Check for two logger calls
  expect(logger.error).toHaveBeenCalledTimes(2);
  
  // First call from `if (!response.ok)`
  expect(logger.error).toHaveBeenNthCalledWith(
    1,
    'Failed to update language preference: 500',
    expect.objectContaining({
      component: 'LanguageSwitcher',
      event: 'updateLanguagePreferenceFailed',
      error_message: 'Internal Server Error', // From response.statusText
      status_code: 500,
    })
  );

  // Second call from `catch` block due to setApiError throwing
  expect(logger.error).toHaveBeenNthCalledWith(
    2,
    'Error updating language preference', // Generic message from catch block
    expect.objectContaining({
      component: 'LanguageSwitcher',
      event: 'updateLanguagePreferenceFailed',
      error_message: errorFromSetApiError.message, // Error from setApiError
      status_code: 'N/A',
    })
  );

  // Restore mocks
  global.fetch = originalFetch;
  mockFailedFetch.mockClear();
  useStateSpy.mockRestore(); // Restore original React.useState
});
```

If this modified test passes (i.e., `logger.error` is called twice), it confirms the bug's existence and its trigger mechanism. The original test at line 210 would then be considered insufficient for catching this specific double-logging scenario because it doesn't simulate the `setApiError` failure.

## 5. Conclusion and Recommendations

**Diagnosis:**
- The test at [`__tests__/components/LanguageSwitcher.test.tsx:210`] currently passes because it expects one `logger.error` call, and under its current mocking (where `setApiError` does not throw), this is the observed behavior.
- The originally reported bug (double `logger.error` call for a 500 error) is a *potential* bug in [`components/LanguageSwitcher.tsx`] that can manifest if `setApiError` throws a synchronous error after the initial `logger.error` call within the `if (!response.ok)` block.
- The original report was likely valid under conditions that caused `setApiError` to fail synchronously.

**Recommendations:**
1.  **Confirm Bug Pathway:** Implement a test similar to the "Proposed Test Modification" above to confirm that a synchronous error in `setApiError` indeed leads to a second `logger.error` call. This test would serve as a regression test for this specific failure mode.
2.  **Address Component Robustness (Optional but Recommended):** Consider if the component's error handling can be made more robust to prevent a `setApiError` failure from triggering a redundant generic log. However, logging an error when a state update itself fails might be desired behavior. The primary issue is ensuring tests cover such scenarios.
3.  **Investigate Skipped Test:** Separately investigate why the test at line 210 "is skipped when run individually." This is crucial for overall test suite health and reliability.
4.  **Update Original Test:** If the bug pathway is confirmed via the new test, decide on the desired behavior:
    *   If double logging in this scenario is considered a bug to be fixed in the component, then the component should be fixed, and the original test (expecting one log) would remain correct for the *fixed* component.
    *   If double logging is an accepted (though perhaps undesirable) consequence of `setApiError` failing, and the goal is to ensure the test *catches* this, then the original test's assertion should be changed to `toHaveBeenCalledTimes(2)` *only when* `setApiError` is mocked to throw. The current test (expecting 1 call) is fine for the scenario where `setApiError` behaves normally. It might be better to have two separate tests: one for the normal 500 error (1 log) and one for the 500 error + `setApiError` failure (2 logs).

The bug is subtle as it depends on the behavior of a React state setter, which usually doesn't throw synchronously in typical test environments.
## 6. Implemented Fix and Resolution

Following the diagnosis, a fix was implemented in the [`components/LanguageSwitcher.tsx`] component to prevent the double `logger.error` call.

**Summary of the Fix:**

1.  **`errorLoggedThisAttempt` Flag:** A boolean flag, `errorLoggedThisAttempt`, was introduced within the `updatePreference` function. It's initialized to `false` at the start of each call.
2.  **Conditional Primary Log:** The initial `logger.error` call (triggered by `!response.ok`) is now conditional. It only executes if `errorLoggedThisAttempt` is `false`. After logging, the flag is set to `true`.
    ```typescript
    // components/LanguageSwitcher.tsx:55-58
    if (!errorLoggedThisAttempt) {
      logger.error(`Failed to update language preference: ${response.status}`, errorContext);
      errorLoggedThisAttempt = true;
    }
    ```
3.  **Refined `catch` Block:** The `catch` block's logging logic was also made conditional on `errorLoggedThisAttempt`. If an error (like one thrown by a mocked `setApiError`) is caught, and `errorLoggedThisAttempt` is already `true` (meaning the primary API error was logged), the `catch` block will not issue a redundant second log. The refined logic (around lines 200-218 in the component) specifically handles the case where `setApiError` might throw, ensuring a log only occurs if no prior log for the attempt was made.

**Impact on Diagnosis:**

This fix directly addresses the diagnosed potential for double logging. By ensuring that only one log is made per attempt of `updatePreference`, the component is now robust against the scenario where `setApiError` (or another operation within the `try` block after the initial error check) might throw an error.

The test case modified to make `setApiError` throw an error (as proposed in section 4 of this report) should now correctly assert that `logger.error` is called only once, thanks to this fix in the component. The original test (`'logs structured error and shows specific message on API server error (500)'` at [`__tests__/components/LanguageSwitcher.test.tsx:210`]) which expected one call, remains valid for the fixed component.

**Resolution:**
The bug pathway identified (double logging when `setApiError` throws after an initial API error log) has been closed by the introduction of the `errorLoggedThisAttempt` flag and the refined conditional logging logic in [`components/LanguageSwitcher.tsx`].